<!DOCTYPE html>
<html>
  <body>
    <!-- 正常情况下，async中的await命令是一个promise对象，返回该对象的结果；
    但是如果不是promise对象的话，就会直接返回对应的值，相当于promise.resolve(); -->


    <!-- 一个async处理错误的题 -->
    <script>
      async function async1() {
        await async2()
        console.log('async1')
        return 'async1 success'
      }
      async function async2() {
        return new Promise((resolve,reject) => {
          console.log('async2')
          reject('error')
        })
      }

      async1().then((res)=> {
        console.log('res:',res)
      })

      /**
       * 执行顺序：
       * async2
       * Promise{<rejected>:'error'}
       * 
       * 解析：
       * 如果在async函数中抛出错误，到终止错误结果，不会继续向下执行，throw new error也是如此
      */
    </script>
  </body>
</html>